Workbook

Sheet ENTREGAS
A1: N° Entrega | B1: Fecha | C1: Productor / Institución | D1: Apellido y Nombre | E1: ¿Está Inscripto? | F1: Producto | G1: Cantidad | H1: Observaciones
A2: =IF(AND(B2="", C2=""), "", "ENT-0001") -> ENT-0001 | B2: 46279 | C2: PROD-018 - ALTAMIRANO SERGIO RAMIRO | D2: {=IF(C2="","",IFERROR(INDEX(PRODUCTORES!$B:$B, MATCH(C2, PRODUCTORES!$F:$F, 0)) & " " & INDEX(PRODUCTORES!$C:$C, MATCH(C2, PRODUCTORES!$F:$F, 0)), IFERROR(INDEX(PRODUCTORES!$B:$B, MATCH(C2, PRODUCTORES!$A:$A, 0)) & " " & INDEX(PRODUCTORES!$C:$C, MATCH(C2, PRODUCTORES!$A:$A, 0)), IFERROR(TRIM(MID(C2, SEARCH(" - ", C2) + 3, 100)), "NO ENCONTRADO"))))} -> ALTAMIRANO SERGIO RAMIRO | E2: {=IF(C2="","",IFERROR(INDEX(PRODUCTORES!$D:$D, MATCH(C2, PRODUCTORES!$F:$F, 0)), IFERROR(INDEX(PRODUCTORES!$D:$D, MATCH(IF(ISNUMBER(SEARCH(" - ", C2)), LEFT(C2, SEARCH(" - ", C2) - 1), C2), PRODUCTORES!$A:$A, 0)), "-")))} -> Sí | F2: Lechuga (Verde / Mantecosa / Criolla) | G2: 4
A3: =IF(AND(B3="", C3=""), "", IF(AND(B3=B2, C3=C2, B3<>""), A2, "ENT-" & TEXT(IFERROR(VALUE(RIGHT(A2, 4)), 0) + 1, "0000"))) -> ENT-0001 | B3: 46279 | C3: PROD-018 - ALTAMIRANO SERGIO RAMIRO | D3: {=IF(C3="","",IFERROR(INDEX(PRODUCTORES!$B:$B, MATCH(C3, PRODUCTORES!$F:$F, 0)) & " " & INDEX(PRODUCTORES!$C:$C, MATCH(C3, PRODUCTORES!$F:$F, 0)), IFERROR(INDEX(PRODUCTORES!$B:$B, MATCH(C3, PRODUCTORES!$A:$A, 0)) & " " & INDEX(PRODUCTORES!$C:$C, MATCH(C3, PRODUCTORES!$A:$A, 0)), IFERROR(TRIM(MID(C3, SEARCH(" - ", C3) + 3, 100)), "NO ENCONTRADO"))))} -> ALTAMIRANO SERGIO RAMIRO | E3: {=IF(C3="","",IFERROR(INDEX(PRODUCTORES!$D:$D, MATCH(C3, PRODUCTORES!$F:$F, 0)), IFERROR(INDEX(PRODUCTORES!$D:$D, MATCH(IF(ISNUMBER(SEARCH(" - ", C3)), LEFT(C3, SEARCH(" - ", C3) - 1), C3), PRODUCTORES!$A:$A, 0)), "-")))} -> Sí | F3: Acelga | G3: 1
A4: =IF(AND(B4="", C4=""), "", IF(AND(B4=B3, C4=C3, B4<>""), A3, "ENT-" & TEXT(IFERROR(VALUE(RIGHT(A3, 4)), 0) + 1, "0000"))) -> ENT-0001 | B4: 46279 | C4: PROD-018 - ALTAMIRANO SERGIO RAMIRO | D4: {=IF(C4="","",IFERROR(INDEX(PRODUCTORES!$B:$B, MATCH(C4, PRODUCTORES!$F:$F, 0)) & " " & INDEX(PRODUCTORES!$C:$C, MATCH(C4, PRODUCTORES!$F:$F, 0)), IFERROR(INDEX(PRODUCTORES!$B:$B, MATCH(C4, PRODUCTORES!$A:$A, 0)) & " " & INDEX(PRODUCTORES!$C:$C, MATCH(C4, PRODUCTORES!$A:$A, 0)), IFERROR(TRIM(MID(C4, SEARCH(" - ", C4) + 3, 100)), "NO ENCONTRADO"))))} -> ALTAMIRANO SERGIO RAMIRO | E4: {=IF(C4="","",IFERROR(INDEX(PRODUCTORES!$D:$D, MATCH(C4, PRODUCTORES!$F:$F, 0)), IFERROR(INDEX(PRODUCTORES!$D:$D, MATCH(IF(ISNUMBER(SEARCH(" - ", C4)), LEFT(C4, SEARCH(" - ", C4) - 1), C4), PRODUCTORES!$A:$A, 0)), "-")))} -> Sí | F4: Perejil | G4: 1
A5: =IF(AND(B5="", C5=""), "", IF(AND(B5=B4, C5=C4, B5<>""), A4, "ENT-" & TEXT(IFERROR(VALUE(RIGHT(A4, 4)), 0) + 1, "0000"))) -> ENT-0001 | B5: 46279 | C5: PROD-018 - ALTAMIRANO SERGIO RAMIRO | D5: {=IF(C5="","",IFERROR(INDEX(PRODUCTORES!$B:$B, MATCH(C5, PRODUCTORES!$F:$F, 0)) & " " & INDEX(PRODUCTORES!$C:$C, MATCH(C5, PRODUCTORES!$F:$F, 0)), IFERROR(INDEX(PRODUCTORES!$B:$B, MATCH(C5, PRODUCTORES!$A:$A, 0)) & " " & INDEX(PRODUCTORES!$C:$C, MATCH(C5, PRODUCTORES!$A:$A, 0)), IFERROR(TRIM(MID(C5, SEARCH(" - ", C5) + 3, 100)), "NO ENCONTRADO"))))} -> ALTAMIRANO SERGIO RAMIRO | E5: {=IF(C5="","",IFERROR(INDEX(PRODUCTORES!$D:$D, MATCH(C5, PRODUCTORES!$F:$F, 0)), IFERROR(INDEX(PRODUCTORES!$D:$D, MATCH(IF(ISNUMBER(SEARCH(" - ", C5)), LEFT(C5, SEARCH(" - ", C5) - 1), C5), PRODUCTORES!$A:$A, 0)), "-")))} -> Sí | F5: Cilantro | G5: 1
A6: =IF(AND(B6="", C6=""), "", IF(AND(B6=B5, C6=C5, B6<>""), A5, "ENT-" & TEXT(IFERROR(VALUE(RIGHT(A5, 4)), 0) + 1, "0000"))) -> ENT-0001 | B6: 46279 | C6: PROD-018 - ALTAMIRANO SERGIO RAMIRO | D6: {=IF(C6="","",IFERROR(INDEX(PRODUCTORES!$B:$B, MATCH(C6, PRODUCTORES!$F:$F, 0)) & " " & INDEX(PRODUCTORES!$C:$C, MATCH(C6, PRODUCTORES!$F:$F, 0)), IFERROR(INDEX(PRODUCTORES!$B:$B, MATCH(C6, PRODUCTORES!$A:$A, 0)) & " " & INDEX(PRODUCTORES!$C:$C, MATCH(C6, PRODUCTORES!$A:$A, 0)), IFERROR(TRIM(MID(C6, SEARCH(" - ", C6) + 3, 100)), "NO ENCONTRADO"))))} -> ALTAMIRANO SERGIO RAMIRO | E6: {=IF(C6="","",IFERROR(INDEX(PRODUCTORES!$D:$D, MATCH(C6, PRODUCTORES!$F:$F, 0)), IFERROR(INDEX(PRODUCTORES!$D:$D, MATCH(IF(ISNUMBER(SEARCH(" - ", C6)), LEFT(C6, SEARCH(" - ", C6) - 1), C6), PRODUCTORES!$A:$A, 0)), "-")))} -> Sí | F6: Cebolla de Verdeo / Verdeo | G6: 1
A7: =IF(AND(B7="", C7=""), "", IF(AND(B7=B6, C7=C6, B7<>""), A6, "ENT-" & TEXT(IFERROR(VALUE(RIGHT(A6, 4)), 0) + 1, "0000"))) -> ENT-0002 | B7: 46279 | C7: PROD-046 - ASTORGA YESSICA | D7: {=IF(C7="","",IFERROR(INDEX(PRODUCTORES!$B:$B, MATCH(C7, PRODUCTORES!$F:$F, 0)) & " " & INDEX(PRODUCTORES!$C:$C, MATCH(C7, PRODUCTORES!$F:$F, 0)), IFERROR(INDEX(PRODUCTORES!$B:$B, MATCH(C7, PRODUCTORES!$A:$A, 0)) & " " & INDEX(PRODUCTORES!$C:$C, MATCH(C7, PRODUCTORES!$A:$A, 0)), IFERROR(TRIM(MID(C7, SEARCH(" - ", C7) + 3, 100)), "NO ENCONTRADO"))))} -> ASTORGA YESSICA | E7: {=IF(C7="","",IFERROR(INDEX(PRODUCTORES!$D:$D, MATCH(C7, PRODUCTORES!$F:$F, 0)), IFERROR(INDEX(PRODUCTORES!$D:$D, MATCH(IF(ISNUMBER(SEARCH(" - ", C7)), LEFT(C7, SEARCH(" - ", C7) - 1), C7), PRODUCTORES!$A:$A, 0)), "-")))} -> Sí | F7: Lechuga (Verde / Mantecosa / Criolla) | G7: 7
A8: =IF(AND(B8="", C8=""), "", IF(AND(B8=B7, C8=C7, B8<>""), A7, "ENT-" & TEXT(IFERROR(VALUE(RIGHT(A7, 4)), 0) + 1, "0000"))) -> ENT-0002 | B8: 46279 | C8: PROD-046 - ASTORGA YESSICA | D8: {=IF(C8="","",IFERROR(INDEX(PRODUCTORES!$B:$B, MATCH(C8, PRODUCTORES!$F:$F, 0)) & " " & INDEX(PRODUCTORES!$C:$C, MATCH(C8, PRODUCTORES!$F:$F, 0)), IFERROR(INDEX(PRODUCTORES!$B:$B, MATCH(C8, PRODUCTORES!$A:$A, 0)) & " " & INDEX(PRODUCTORES!$C:$C, MATCH(C8, PRODUCTORES!$A:$A, 0)), IFERROR(TRIM(MID(C8, SEARCH(" - ", C8) + 3, 100)), "NO ENCONTRADO"))))} -> ASTORGA YESSICA | E8: {=IF(C8="","",IFERROR(INDEX(PRODUCTORES!$D:$D, MATCH(C8, PRODUCTORES!$F:$F, 0)), IFERROR(INDEX(PRODUCTORES!$D:$D, MATCH(IF(ISNUMBER(SEARCH(" - ", C8)), LEFT(C8, SEARCH(" - ", C8) - 1), C8), PRODUCTORES!$A:$A, 0)), "-")))} -> Sí | F8: Acelga | G8: 6
A9: =IF(AND(B9="", C9=""), "", IF(AND(B9=B8, C9=C8, B9<>""), A8, "ENT-" & TEXT(IFERROR(VALUE(RIGHT(A8, 4)), 0) + 1, "0000"))) -> ENT-0002 | B9: 46279 | C9: PROD-046 - ASTORGA YESSICA | D9: {=IF(C9="","",IFERROR(INDEX(PRODUCTORES!$B:$B, MATCH(C9, PRODUCTORES!$F:$F, 0)) & " " & INDEX(PRODUCTORES!$C:$C, MATCH(C9, PRODUCTORES!$F:$F, 0)), IFERROR(INDEX(PRODUCTORES!$B:$B, MATCH(C9, PRODUCTORES!$A:$A, 0)) & " " & INDEX(PRODUCTORES!$C:$C, MATCH(C9, PRODUCTORES!$A:$A, 0)), IFERROR(TRIM(MID(C9, SEARCH(" - ", C9) + 3, 100)), "NO ENCONTRADO"))))} -> ASTORGA YESSICA | E9: {=IF(C9="","",IFERROR(INDEX(PRODUCTORES!$D:$D, MATCH(C9, PRODUCTORES!$F:$F, 0)), IFERROR(INDEX(PRODUCTORES!$D:$D, MATCH(IF(ISNUMBER(SEARCH(" - ", C9)), LEFT(C9, SEARCH(" - ", C9) - 1), C9), PRODUCTORES!$A:$A, 0)), "-")))} -> Sí | F9: Rúcula | G9: 3
A10: =IF(AND(B10="", C10=""), "", IF(AND(B10=B9, C10=C9, B10<>""), A9, "ENT-" & TEXT(IFERROR(VALUE(RIGHT(A9, 4)), 0) + 1, "0000"))) -> ENT-0003 | B10: 46279 | C10: PROD-037 - ARAOZ CORI VICTOR | D10: {=IF(C10="","",IFERROR(INDEX(PRODUCTORES!$B:$B, MATCH(C10, PRODUCTORES!$F:$F, 0)) & " " & INDEX(PRODUCTORES!$C:$C, MATCH(C10, PRODUCTORES!$F:$F, 0)), IFERROR(INDEX(PRODUCTORES!$B:$B, MATCH(C10, PRODUCTORES!$A:$A, 0)) & " " & INDEX(PRODUCTORES!$C:$C, MATCH(C10, PRODUCTORES!$A:$A, 0)), IFERROR(TRIM(MID(C10, SEARCH(" - ", C10) + 3, 100)), "NO ENCONTRADO"))))} -> ARAOZ CORI VICTOR | E10: {=IF(C10="","",IFERROR(INDEX(PRODUCTORES!$D:$D, MATCH(C10, PRODUCTORES!$F:$F, 0)), IFERROR(INDEX(PRODUCTORES!$D:$D, MATCH(IF(ISNUMBER(SEARCH(" - ", C10)), LEFT(C10, SEARCH(" - ", C10) - 1), C10), PRODUCTORES!$A:$A, 0)), "-")))} -> Sí | F10: Lechuga (Verde / Mantecosa / Criolla) | G10: 4
A11: =IF(AND(B11="", C11=""), "", IF(AND(B11=B10, C11=C10, B11<>""), A10, "ENT-" & TEXT(IFERROR(VALUE(RIGHT(A10, 4)), 0) + 1, "0000"))) -> ENT-0003 | B11: 46279 | C11: PROD-037 - ARAOZ CORI VICTOR | D11: {=IF(C11="","",IFERROR(INDEX(PRODUCTORES!$B:$B, MATCH(C11, PRODUCTORES!$F:$F, 0)) & " " & INDEX(PRODUCTORES!$C:$C, MATCH(C11, PRODUCTORES!$F:$F, 0)), IFERROR(INDEX(PRODUCTORES!$B:$B, MATCH(C11, PRODUCTORES!$A:$A, 0)) & " " & INDEX(PRODUCTORES!$C:$C, MATCH(C11, PRODUCTORES!$A:$A, 0)), IFERROR(TRIM(MID(C11, SEARCH(" - ", C11) + 3, 100)), "NO ENCONTRADO"))))} -> ARAOZ CORI VICTOR | E11: {=IF(C11="","",IFERROR(INDEX(PRODUCTORES!$D:$D, MATCH(C11, PRODUCTORES!$F:$F, 0)), IFERROR(INDEX(PRODUCTORES!$D:$D, MATCH(IF(ISNUMBER(SEARCH(" - ", C11)), LEFT(C11, SEARCH(" - ", C11) - 1), C11), PRODUCTORES!$A:$A, 0)), "-")))} -> Sí | F11: Perejil | G11: 1
A12: =IF(AND(B12="", C12=""), "", IF(AND(B12=B11, C12=C11, B12<>""), A11, "ENT-" & TEXT(IFERROR(VALUE(RIGHT(A11, 4)), 0) + 1, "0000"))) -> ENT-0003 | B12: 46279 | C12: PROD-037 - ARAOZ CORI VICTOR | D12: {=IF(C12="","",IFERROR(INDEX(PRODUCTORES!$B:$B, MATCH(C12, PRODUCTORES!$F:$F, 0)) & " " & INDEX(PRODUCTORES!$C:$C, MATCH(C12, PRODUCTORES!$F:$F, 0)), IFERROR(INDEX(PRODUCTORES!$B:$B, MATCH(C12, PRODUCTORES!$A:$A, 0)) & " " & INDEX(PRODUCTORES!$C:$C, MATCH(C12, PRODUCTORES!$A:$A, 0)), IFERROR(TRIM(MID(C12, SEARCH(" - ", C12) + 3, 100)), "NO ENCONTRADO"))))} -> ARAOZ CORI VICTOR | E12: {=IF(C12="","",IFERROR(INDEX(PRODUCTORES!$D:$D, MATCH(C12, PRODUCTORES!$F:$F, 0)), IFERROR(INDEX(PRODUCTORES!$D:$D, MATCH(IF(ISNUMBER(SEARCH(" - ", C12)), LEFT(C12, SEARCH(" - ", C12) - 1), C12), PRODUCTORES!$A:$A, 0)), "-")))} -> Sí | F12: Cebolla de Verdeo / Verdeo | G12: 1
A13: =IF(AND(B13="", C13=""), "", IF(AND(B13=B12, C13=C12, B13<>""), A12, "ENT-" & TEXT(IFERROR(VALUE(RIGHT(A12, 4)), 0) + 1, "0000"))) -> ENT-0003 | B13: 46279 | C13: PROD-037 - ARAOZ CORI VICTOR | D13: {=IF(C13="","",IFERROR(INDEX(PRODUCTORES!$B:$B, MATCH(C13, PRODUCTORES!$F:$F, 0)) & " " & INDEX(PRODUCTORES!$C:$C, MATCH(C13, PRODUCTORES!$F:$F, 0)), IFERROR(INDEX(PRODUCTORES!$B:$B, MATCH(C13, PRODUCTORES!$A:$A, 0)) & " " & INDEX(PRODUCTORES!$C:$C, MATCH(C13, PRODUCTORES!$A:$A, 0)), IFERROR(TRIM(MID(C13, SEARCH(" - ", C13) + 3, 100)), "NO ENCONTRADO"))))} -> ARAOZ CORI VICTOR | E13: {=IF(C13="","",IFERROR(INDEX(PRODUCTORES!$D:$D, MATCH(C13, PRODUCTORES!$F:$F, 0)), IFERROR(INDEX(PRODUCTORES!$D:$D, MATCH(IF(ISNUMBER(SEARCH(" - ", C13)), LEFT(C13, SEARCH(" - ", C13) - 1), C13), PRODUCTORES!$A:$A, 0)), "-")))} -> Sí | F13: Apio | G13: 1
A14: =IF(AND(B14="", C14=""), "", IF(AND(B14=B13, C14=C13, B14<>""), A13, "ENT-" & TEXT(IFERROR(VALUE(RIGHT(A13, 4)), 0) + 1, "0000"))) -> ENT-0004 | B14: 46279 | C14: PROD-052 - BALCAZAR VILLARROEL SILVIA DEL CARMEN | D14: {=IF(C14="","",IFERROR(INDEX(PRODUCTORES!$B:$B, MATCH(C14, PRODUCTORES!$F:$F, 0)) & " " & INDEX(PRODUCTORES!$C:$C, MATCH(C14, PRODUCTORES!$F:$F, 0)), IFERROR(INDEX(PRODUCTORES!$B:$B, MATCH(C14, PRODUCTORES!$A:$A, 0)) & " " & INDEX(PRODUCTORES!$C:$C, MATCH(C14, PRODUCTORES!$A:$A, 0)), IFERROR(TRIM(MID(C14, SEARCH(" - ", C14) + 3, 100)), "NO ENCONTRADO"))))} -> BALCAZAR VILLARROEL SILVIA DEL CARMEN | E14: {=IF(C14="","",IFERROR(INDEX(PRODUCTORES!$D:$D, MATCH(C14, PRODUCTORES!$F:$F, 0)), IFERROR(INDEX(PRODUCTORES!$D:$D, MATCH(IF(ISNUMBER(SEARCH(" - ", C14)), LEFT(C14, SEARCH(" - ", C14) - 1), C14), PRODUCTORES!$A:$A, 0)), "-")))} -> Sí | F14: Lechuga (Verde / Mantecosa / Criolla) | G14: 1
... A263: =IF(AND(B263="", C263=""), "", IF(AND(B263=B262, C263=C262, B263<>""), A262, "ENT-" & TEXT(IFERROR(VALUE(RIGHT(A262, 4)), 0) + 1, "0000"))) -> ENT-0071 | B263: 46282 | C263: PROD-358 - VALDIVIA DIEGO | D263: {=IF(C263="","",IFERROR(INDEX(PRODUCTORES!$B:$B, MATCH(C263, PRODUCTORES!$F:$F, 0)) & " " & INDEX(PRODUCTORES!$C:$C, MATCH(C263, PRODUCTORES!$F:$F, 0)), IFERROR(INDEX(PRODUCTORES!$B:$B, MATCH(C263, PRODUCTORES!$A:$A, 0)) & " " & INDEX(PRODUCTORES!$C:$C, MATCH(C263, PRODUCTORES!$A:$A, 0)), IFERROR(TRIM(MID(C263, SEARCH(" - ", C263) + 3, 100)), "NO ENCONTRADO"))))} -> VALDIVIA DIEGO | E263: {=IF(C263="","",IFERROR(INDEX(PRODUCTORES!$D:$D, MATCH(C263, PRODUCTORES!$F:$F, 0)), IFERROR(INDEX(PRODUCTORES!$D:$D, MATCH(IF(ISNUMBER(SEARCH(" - ", C263)), LEFT(C263, SEARCH(" - ", C263) - 1), C263), PRODUCTORES!$A:$A, 0)), "-")))} -> Sí | F263: Repollo (Verde / Morado) | G263: 2
A264: =IF(AND(B264="", C264=""), "", IF(AND(B264=B263, C264=C263, B264<>""), A263, "ENT-" & TEXT(IFERROR(VALUE(RIGHT(A263, 4)), 0) + 1, "0000"))) -> ENT-0071 | B264: =IF(AND(C264="", D264=""), "", IF(AND(C264=C263, D264=D263, C264<>""), B263, "ENT-" & TEXT(IFERROR(VALUE(RIGHT(B263, 4)), 0) + 1, "0000"))) -> 46282 | C264: PROD-358 - VALDIVIA DIEGO | D264: {=IF(C264="","",IFERROR(INDEX(PRODUCTORES!$B:$B, MATCH(C264, PRODUCTORES!$F:$F, 0)) & " " & INDEX(PRODUCTORES!$C:$C, MATCH(C264, PRODUCTORES!$F:$F, 0)), IFERROR(INDEX(PRODUCTORES!$B:$B, MATCH(C264, PRODUCTORES!$A:$A, 0)) & " " & INDEX(PRODUCTORES!$C:$C, MATCH(C264, PRODUCTORES!$A:$A, 0)), IFERROR(TRIM(MID(C264, SEARCH(" - ", C264) + 3, 100)), "NO ENCONTRADO"))))} -> VALDIVIA DIEGO | E264: {=IF(C264="","",IFERROR(INDEX(PRODUCTORES!$D:$D, MATCH(C264, PRODUCTORES!$F:$F, 0)), IFERROR(INDEX(PRODUCTORES!$D:$D, MATCH(IF(ISNUMBER(SEARCH(" - ", C264)), LEFT(C264, SEARCH(" - ", C264) - 1), C264), PRODUCTORES!$A:$A, 0)), "-")))} -> Sí | F264: Lechuga (Verde / Mantecosa / Criolla) | G264: 2
A265: =IF(AND(B265="", C265=""), "", IF(AND(B265=B264, C265=C264, B265<>""), A264, "ENT-" & TEXT(IFERROR(VALUE(RIGHT(A264, 4)), 0) + 1, "0000"))) -> ENT-0072 | B265: 46282 | C265: PROD-090 - RODRIGUEZ CARLOS ANTONIO | D265: {=IF(C265="","",IFERROR(INDEX(PRODUCTORES!$B:$B, MATCH(C265, PRODUCTORES!$F:$F, 0)) & " " & INDEX(PRODUCTORES!$C:$C, MATCH(C265, PRODUCTORES!$F:$F, 0)), IFERROR(INDEX(PRODUCTORES!$B:$B, MATCH(C265, PRODUCTORES!$A:$A, 0)) & " " & INDEX(PRODUCTORES!$C:$C, MATCH(C265, PRODUCTORES!$A:$A, 0)), IFERROR(TRIM(MID(C265, SEARCH(" - ", C265) + 3, 100)), "NO ENCONTRADO"))))} -> RODRIGUEZ CARLOS ANTONIO | E265: {=IF(C265="","",IFERROR(INDEX(PRODUCTORES!$D:$D, MATCH(C265, PRODUCTORES!$F:$F, 0)), IFERROR(INDEX(PRODUCTORES!$D:$D, MATCH(IF(ISNUMBER(SEARCH(" - ", C265)), LEFT(C265, SEARCH(" - ", C265) - 1), C265), PRODUCTORES!$A:$A, 0)), "-")))} -> Sí | F265: Lechuga (Verde / Mantecosa / Criolla) | G265: 6
A266: =IF(AND(B266="", C266=""), "", IF(AND(B266=B265, C266=C265, B266<>""), A265, "ENT-" & TEXT(IFERROR(VALUE(RIGHT(A265, 4)), 0) + 1, "0000"))) -> ENT-0072 | B266: 46282 | C266: PROD-090 - RODRIGUEZ CARLOS ANTONIO | D266: {=IF(C266="","",IFERROR(INDEX(PRODUCTORES!$B:$B, MATCH(C266, PRODUCTORES!$F:$F, 0)) & " " & INDEX(PRODUCTORES!$C:$C, MATCH(C266, PRODUCTORES!$F:$F, 0)), IFERROR(INDEX(PRODUCTORES!$B:$B, MATCH(C266, PRODUCTORES!$A:$A, 0)) & " " & INDEX(PRODUCTORES!$C:$C, MATCH(C266, PRODUCTORES!$A:$A, 0)), IFERROR(TRIM(MID(C266, SEARCH(" - ", C266) + 3, 100)), "NO ENCONTRADO"))))} -> RODRIGUEZ CARLOS ANTONIO | E266: {=IF(C266="","",IFERROR(INDEX(PRODUCTORES!$D:$D, MATCH(C266, PRODUCTORES!$F:$F, 0)), IFERROR(INDEX(PRODUCTORES!$D:$D, MATCH(IF(ISNUMBER(SEARCH(" - ", C266)), LEFT(C266, SEARCH(" - ", C266) - 1), C266), PRODUCTORES!$A:$A, 0)), "-")))} -> Sí | F266: Rúcula | G266: 2
A267: =IF(AND(B267="", C267=""), "", IF(AND(B267=B266, C267=C266, B267<>""), A266, "ENT-" & TEXT(IFERROR(VALUE(RIGHT(A266, 4)), 0) + 1, "0000"))) -> ENT-0072 | B267: 46282 | C267: PROD-090 - RODRIGUEZ CARLOS ANTONIO | D267: {=IF(C267="","",IFERROR(INDEX(PRODUCTORES!$B:$B, MATCH(C267, PRODUCTORES!$F:$F, 0)) & " " & INDEX(PRODUCTORES!$C:$C, MATCH(C267, PRODUCTORES!$F:$F, 0)), IFERROR(INDEX(PRODUCTORES!$B:$B, MATCH(C267, PRODUCTORES!$A:$A, 0)) & " " & INDEX(PRODUCTORES!$C:$C, MATCH(C267, PRODUCTORES!$A:$A, 0)), IFERROR(TRIM(MID(C267, SEARCH(" - ", C267) + 3, 100)), "NO ENCONTRADO"))))} -> RODRIGUEZ CARLOS ANTONIO | E267: {=IF(C267="","",IFERROR(INDEX(PRODUCTORES!$D:$D, MATCH(C267, PRODUCTORES!$F:$F, 0)), IFERROR(INDEX(PRODUCTORES!$D:$D, MATCH(IF(ISNUMBER(SEARCH(" - ", C267)), LEFT(C267, SEARCH(" - ", C267) - 1), C267), PRODUCTORES!$A:$A, 0)), "-")))} -> Sí | F267: Perejil | G267: 1
A268: =IF(AND(B268="", C268=""), "", IF(AND(B268=B267, C268=C267, B268<>""), A267, "ENT-" & TEXT(IFERROR(VALUE(RIGHT(A267, 4)), 0) + 1, "0000"))) -> ENT-0072 | B268: 46282 | C268: PROD-090 - RODRIGUEZ CARLOS ANTONIO | D268: {=IF(C268="","",IFERROR(INDEX(PRODUCTORES!$B:$B, MATCH(C268, PRODUCTORES!$F:$F, 0)) & " " & INDEX(PRODUCTORES!$C:$C, MATCH(C268, PRODUCTORES!$F:$F, 0)), IFERROR(INDEX(PRODUCTORES!$B:$B, MATCH(C268, PRODUCTORES!$A:$A, 0)) & " " & INDEX(PRODUCTORES!$C:$C, MATCH(C268, PRODUCTORES!$A:$A, 0)), IFERROR(TRIM(MID(C268, SEARCH(" - ", C268) + 3, 100)), "NO ENCONTRADO"))))} -> RODRIGUEZ CARLOS ANTONIO | E268: {=IF(C268="","",IFERROR(INDEX(PRODUCTORES!$D:$D, MATCH(C268, PRODUCTORES!$F:$F, 0)), IFERROR(INDEX(PRODUCTORES!$D:$D, MATCH(IF(ISNUMBER(SEARCH(" - ", C268)), LEFT(C268, SEARCH(" - ", C268) - 1), C268), PRODUCTORES!$A:$A, 0)), "-")))} -> Sí | F268: Espinaca | G268: 1
A269: =IF(AND(B269="", C269=""), "", IF(AND(B269=B268, C269=C268, B269<>""), A268, "ENT-" & TEXT(IFERROR(VALUE(RIGHT(A268, 4)), 0) + 1, "0000"))) -> ENT-0073 | B269: 46282 | C269: PROD-227 - MANSILLA IRIS | D269: {=IF(C269="","",IFERROR(INDEX(PRODUCTORES!$B:$B, MATCH(C269, PRODUCTORES!$F:$F, 0)) & " " & INDEX(PRODUCTORES!$C:$C, MATCH(C269, PRODUCTORES!$F:$F, 0)), IFERROR(INDEX(PRODUCTORES!$B:$B, MATCH(C269, PRODUCTORES!$A:$A, 0)) & " " & INDEX(PRODUCTORES!$C:$C, MATCH(C269, PRODUCTORES!$A:$A, 0)), IFERROR(TRIM(MID(C269, SEARCH(" - ", C269) + 3, 100)), "NO ENCONTRADO"))))} -> MANSILLA IRIS | E269: {=IF(C269="","",IFERROR(INDEX(PRODUCTORES!$D:$D, MATCH(C269, PRODUCTORES!$F:$F, 0)), IFERROR(INDEX(PRODUCTORES!$D:$D, MATCH(IF(ISNUMBER(SEARCH(" - ", C269)), LEFT(C269, SEARCH(" - ", C269) - 1), C269), PRODUCTORES!$A:$A, 0)), "-")))} -> Sí | F269: Lechuga (Verde / Mantecosa / Criolla) | G269: 6
A270: =IF(AND(B270="", C270=""), "", IF(AND(B270=B269, C270=C269, B270<>""), A269, "ENT-" & TEXT(IFERROR(VALUE(RIGHT(A269, 4)), 0) + 1, "0000"))) -> ENT-0073 | B270: =IF(AND(C270="", D270=""), "", IF(AND(C270=C269, D270=D269, C270<>""), B269, "ENT-" & TEXT(IFERROR(VALUE(RIGHT(B269, 4)), 0) + 1, "0000"))) -> 46282 | C270: PROD-227 - MANSILLA IRIS | D270: {=IF(C270="","",IFERROR(INDEX(PRODUCTORES!$B:$B, MATCH(C270, PRODUCTORES!$F:$F, 0)) & " " & INDEX(PRODUCTORES!$C:$C, MATCH(C270, PRODUCTORES!$F:$F, 0)), IFERROR(INDEX(PRODUCTORES!$B:$B, MATCH(C270, PRODUCTORES!$A:$A, 0)) & " " & INDEX(PRODUCTORES!$C:$C, MATCH(C270, PRODUCTORES!$A:$A, 0)), IFERROR(TRIM(MID(C270, SEARCH(" - ", C270) + 3, 100)), "NO ENCONTRADO"))))} -> MANSILLA IRIS | E270: {=IF(C270="","",IFERROR(INDEX(PRODUCTORES!$D:$D, MATCH(C270, PRODUCTORES!$F:$F, 0)), IFERROR(INDEX(PRODUCTORES!$D:$D, MATCH(IF(ISNUMBER(SEARCH(" - ", C270)), LEFT(C270, SEARCH(" - ", C270) - 1), C270), PRODUCTORES!$A:$A, 0)), "-")))} -> Sí | F270: Rúcula | G270: 4
A271: =IF(AND(B271="", C271=""), "", IF(AND(B271=B270, C271=C270, B271<>""), A270, "ENT-" & TEXT(IFERROR(VALUE(RIGHT(A270, 4)), 0) + 1, "0000"))) -> ENT-0074 | B271: 46282 | C271: AUCHODE ERNESTO | D271: {=IF(C271="","",IFERROR(INDEX(PRODUCTORES!$B:$B, MATCH(C271, PRODUCTORES!$F:$F, 0)) & " " & INDEX(PRODUCTORES!$C:$C, MATCH(C271, PRODUCTORES!$F:$F, 0)), IFERROR(INDEX(PRODUCTORES!$B:$B, MATCH(C271, PRODUCTORES!$A:$A, 0)) & " " & INDEX(PRODUCTORES!$C:$C, MATCH(C271, PRODUCTORES!$A:$A, 0)), IFERROR(TRIM(MID(C271, SEARCH(" - ", C271) + 3, 100)), "NO ENCONTRADO"))))} -> NO ENCONTRADO | E271: {=IF(C271="","",IFERROR(INDEX(PRODUCTORES!$D:$D, MATCH(C271, PRODUCTORES!$F:$F, 0)), IFERROR(INDEX(PRODUCTORES!$D:$D, MATCH(IF(ISNUMBER(SEARCH(" - ", C271)), LEFT(C271, SEARCH(" - ", C271) - 1), C271), PRODUCTORES!$A:$A, 0)), "-")))} -> - | F271: Lechuga (Verde / Mantecosa / Criolla) | G271: 4
A272: =IF(AND(B272="", C272=""), "", IF(AND(B272=B271, C272=C271, B272<>""), A271, "ENT-" & TEXT(IFERROR(VALUE(RIGHT(A271, 4)), 0) + 1, "0000"))) -> ENT-0075 | B272: 46282 | C272: PROD-291 - OYARZO JUAN | D272: {=IF(C272="","",IFERROR(INDEX(PRODUCTORES!$B:$B, MATCH(C272, PRODUCTORES!$F:$F, 0)) & " " & INDEX(PRODUCTORES!$C:$C, MATCH(C272, PRODUCTORES!$F:$F, 0)), IFERROR(INDEX(PRODUCTORES!$B:$B, MATCH(C272, PRODUCTORES!$A:$A, 0)) & " " & INDEX(PRODUCTORES!$C:$C, MATCH(C272, PRODUCTORES!$A:$A, 0)), IFERROR(TRIM(MID(C272, SEARCH(" - ", C272) + 3, 100)), "NO ENCONTRADO"))))} -> OYARZO JUAN | E272: {=IF(C272="","",IFERROR(INDEX(PRODUCTORES!$D:$D, MATCH(C272, PRODUCTORES!$F:$F, 0)), IFERROR(INDEX(PRODUCTORES!$D:$D, MATCH(IF(ISNUMBER(SEARCH(" - ", C272)), LEFT(C272, SEARCH(" - ", C272) - 1), C272), PRODUCTORES!$A:$A, 0)), "-")))} -> Sí | F272: Lechuga (Verde / Mantecosa / Criolla) | G272: 4
A273: =IF(AND(B273="", C273=""), "", IF(AND(B273=B272, C273=C272, B273<>""), A272, "ENT-" & TEXT(IFERROR(VALUE(RIGHT(A272, 4)), 0) + 1, "0000"))) -> ENT-0075 | B273: 46282 | C273: PROD-291 - OYARZO JUAN | D273: {=IF(C273="","",IFERROR(INDEX(PRODUCTORES!$B:$B, MATCH(C273, PRODUCTORES!$F:$F, 0)) & " " & INDEX(PRODUCTORES!$C:$C, MATCH(C273, PRODUCTORES!$F:$F, 0)), IFERROR(INDEX(PRODUCTORES!$B:$B, MATCH(C273, PRODUCTORES!$A:$A, 0)) & " " & INDEX(PRODUCTORES!$C:$C, MATCH(C273, PRODUCTORES!$A:$A, 0)), IFERROR(TRIM(MID(C273, SEARCH(" - ", C273) + 3, 100)), "NO ENCONTRADO"))))} -> OYARZO JUAN | E273: {=IF(C273="","",IFERROR(INDEX(PRODUCTORES!$D:$D, MATCH(C273, PRODUCTORES!$F:$F, 0)), IFERROR(INDEX(PRODUCTORES!$D:$D, MATCH(IF(ISNUMBER(SEARCH(" - ", C273)), LEFT(C273, SEARCH(" - ", C273) - 1), C273), PRODUCTORES!$A:$A, 0)), "-")))} -> Sí | F273: Perejil | G273: 1
A274: =IF(AND(B274="", C274=""), "", IF(AND(B274=B273, C274=C273, B274<>""), A273, "ENT-" & TEXT(IFERROR(VALUE(RIGHT(A273, 4)), 0) + 1, "0000"))) -> ENT-0075 | B274: 46282 | C274: PROD-291 - OYARZO JUAN | D274: {=IF(C274="","",IFERROR(INDEX(PRODUCTORES!$B:$B, MATCH(C274, PRODUCTORES!$F:$F, 0)) & " " & INDEX(PRODUCTORES!$C:$C, MATCH(C274, PRODUCTORES!$F:$F, 0)), IFERROR(INDEX(PRODUCTORES!$B:$B, MATCH(C274, PRODUCTORES!$A:$A, 0)) & " " & INDEX(PRODUCTORES!$C:$C, MATCH(C274, PRODUCTORES!$A:$A, 0)), IFERROR(TRIM(MID(C274, SEARCH(" - ", C274) + 3, 100)), "NO ENCONTRADO"))))} -> OYARZO JUAN | E274: {=IF(C274="","",IFERROR(INDEX(PRODUCTORES!$D:$D, MATCH(C274, PRODUCTORES!$F:$F, 0)), IFERROR(INDEX(PRODUCTORES!$D:$D, MATCH(IF(ISNUMBER(SEARCH(" - ", C274)), LEFT(C274, SEARCH(" - ", C274) - 1), C274), PRODUCTORES!$A:$A, 0)), "-")))} -> Sí | F274: Rúcula | G274: 1
A275: =IF(AND(B275="", C275=""), "", IF(AND(B275=B274, C275=C274, B275<>""), A274, "ENT-" & TEXT(IFERROR(VALUE(RIGHT(A274, 4)), 0) + 1, "0000"))) -> ENT-0075 | B275: 46282 | C275: PROD-291 - OYARZO JUAN | D275: {=IF(C275="","",IFERROR(INDEX(PRODUCTORES!$B:$B, MATCH(C275, PRODUCTORES!$F:$F, 0)) & " " & INDEX(PRODUCTORES!$C:$C, MATCH(C275, PRODUCTORES!$F:$F, 0)), IFERROR(INDEX(PRODUCTORES!$B:$B, MATCH(C275, PRODUCTORES!$A:$A, 0)) & " " & INDEX(PRODUCTORES!$C:$C, MATCH(C275, PRODUCTORES!$A:$A, 0)), IFERROR(TRIM(MID(C275, SEARCH(" - ", C275) + 3, 100)), "NO ENCONTRADO"))))} -> OYARZO JUAN | E275: {=IF(C275="","",IFERROR(INDEX(PRODUCTORES!$D:$D, MATCH(C275, PRODUCTORES!$F:$F, 0)), IFERROR(INDEX(PRODUCTORES!$D:$D, MATCH(IF(ISNUMBER(SEARCH(" - ", C275)), LEFT(C275, SEARCH(" - ", C275) - 1), C275), PRODUCTORES!$A:$A, 0)), "-")))} -> Sí | F275: Repollo (Verde / Morado) | G275: 1
A276: =IF(AND(B276="", C276=""), "", IF(AND(B276=B275, C276=C275, B276<>""), A275, "ENT-" & TEXT(IFERROR(VALUE(RIGHT(A275, 4)), 0) + 1, "0000"))) -> ENT-0076 | B276: 46282 | C276: PROD-270 - NAHUELQUEN LEVI HAIDEE IVETT | D276: {=IF(C276="","",IFERROR(INDEX(PRODUCTORES!$B:$B, MATCH(C276, PRODUCTORES!$F:$F, 0)) & " " & INDEX(PRODUCTORES!$C:$C, MATCH(C276, PRODUCTORES!$F:$F, 0)), IFERROR(INDEX(PRODUCTORES!$B:$B, MATCH(C276, PRODUCTORES!$A:$A, 0)) & " " & INDEX(PRODUCTORES!$C:$C, MATCH(C276, PRODUCTORES!$A:$A, 0)), IFERROR(TRIM(MID(C276, SEARCH(" - ", C276) + 3, 100)), "NO ENCONTRADO"))))} -> NAHUELQUEN LEVI HAIDEE IVETT | E276: {=IF(C276="","",IFERROR(INDEX(PRODUCTORES!$D:$D, MATCH(C276, PRODUCTORES!$F:$F, 0)), IFERROR(INDEX(PRODUCTORES!$D:$D, MATCH(IF(ISNUMBER(SEARCH(" - ", C276)), LEFT(C276, SEARCH(" - ", C276) - 1), C276), PRODUCTORES!$A:$A, 0)), "-")))} -> Sí | F276: Lechuga (Verde / Mantecosa / Criolla) | G276: 6
A277: =IF(AND(B277="", C277=""), "", IF(AND(B277=B276, C277=C276, B277<>""), A276, "ENT-" & TEXT(IFERROR(VALUE(RIGHT(A276, 4)), 0) + 1, "0000"))) -> ENT-0076 | B277: 46282 | C277: PROD-270 - NAHUELQUEN LEVI HAIDEE IVETT | D277: {=IF(C277="","",IFERROR(INDEX(PRODUCTORES!$B:$B, MATCH(C277, PRODUCTORES!$F:$F, 0)) & " " & INDEX(PRODUCTORES!$C:$C, MATCH(C277, PRODUCTORES!$F:$F, 0)), IFERROR(INDEX(PRODUCTORES!$B:$B, MATCH(C277, PRODUCTORES!$A:$A, 0)) & " " & INDEX(PRODUCTORES!$C:$C, MATCH(C277, PRODUCTORES!$A:$A, 0)), IFERROR(TRIM(MID(C277, SEARCH(" - ", C277) + 3, 100)), "NO ENCONTRADO"))))} -> NAHUELQUEN LEVI HAIDEE IVETT | E277: {=IF(C277="","",IFERROR(INDEX(PRODUCTORES!$D:$D, MATCH(C277, PRODUCTORES!$F:$F, 0)), IFERROR(INDEX(PRODUCTORES!$D:$D, MATCH(IF(ISNUMBER(SEARCH(" - ", C277)), LEFT(C277, SEARCH(" - ", C277) - 1), C277), PRODUCTORES!$A:$A, 0)), "-")))} -> Sí | F277: Rúcula | G277: 2
A278: =IF(AND(B278="", C278=""), "", IF(AND(B278=B277, C278=C277, B278<>""), A277, "ENT-" & TEXT(IFERROR(VALUE(RIGHT(A277, 4)), 0) + 1, "0000"))) -> ENT-0076 | B278: 46282 | C278: PROD-270 - NAHUELQUEN LEVI HAIDEE IVETT | D278: {=IF(C278="","",IFERROR(INDEX(PRODUCTORES!$B:$B, MATCH(C278, PRODUCTORES!$F:$F, 0)) & " " & INDEX(PRODUCTORES!$C:$C, MATCH(C278, PRODUCTORES!$F:$F, 0)), IFERROR(INDEX(PRODUCTORES!$B:$B, MATCH(C278, PRODUCTORES!$A:$A, 0)) & " " & INDEX(PRODUCTORES!$C:$C, MATCH(C278, PRODUCTORES!$A:$A, 0)), IFERROR(TRIM(MID(C278, SEARCH(" - ", C278) + 3, 100)), "NO ENCONTRADO"))))} -> NAHUELQUEN LEVI HAIDEE IVETT | E278: {=IF(C278="","",IFERROR(INDEX(PRODUCTORES!$D:$D, MATCH(C278, PRODUCTORES!$F:$F, 0)), IFERROR(INDEX(PRODUCTORES!$D:$D, MATCH(IF(ISNUMBER(SEARCH(" - ", C278)), LEFT(C278, SEARCH(" - ", C278) - 1), C278), PRODUCTORES!$A:$A, 0)), "-")))} -> Sí | F278: Orégano | G278: 1
A279: =IF(AND(B279="", C279=""), "", IF(AND(B279=B278, C279=C278, B279<>""), A278, "ENT-" & TEXT(IFERROR(VALUE(RIGHT(A278, 4)), 0) + 1, "0000"))) -> ENT-0076 | B279: 46282 | C279: PROD-270 - NAHUELQUEN LEVI HAIDEE IVETT | D279: {=IF(C279="","",IFERROR(INDEX(PRODUCTORES!$B:$B, MATCH(C279, PRODUCTORES!$F:$F, 0)) & " " & INDEX(PRODUCTORES!$C:$C, MATCH(C279, PRODUCTORES!$F:$F, 0)), IFERROR(INDEX(PRODUCTORES!$B:$B, MATCH(C279, PRODUCTORES!$A:$A, 0)) & " " & INDEX(PRODUCTORES!$C:$C, MATCH(C279, PRODUCTORES!$A:$A, 0)), IFERROR(TRIM(MID(C279, SEARCH(" - ", C279) + 3, 100)), "NO ENCONTRADO"))))} -> NAHUELQUEN LEVI HAIDEE IVETT | E279: {=IF(C279="","",IFERROR(INDEX(PRODUCTORES!$D:$D, MATCH(C279, PRODUCTORES!$F:$F, 0)), IFERROR(INDEX(PRODUCTORES!$D:$D, MATCH(IF(ISNUMBER(SEARCH(" - ", C279)), LEFT(C279, SEARCH(" - ", C279) - 1), C279), PRODUCTORES!$A:$A, 0)), "-")))} -> Sí | F279: Perejil | G279: 1
A280: =IF(AND(B280="", C280=""), "", IF(AND(B280=B279, C280=C279, B280<>""), A279, "ENT-" & TEXT(IFERROR(VALUE(RIGHT(A279, 4)), 0) + 1, "0000"))) -> ENT-0077 | B280: 46282 | C280: PROD-145 - GARAY JOSE | D280: {=IF(C280="","",IFERROR(INDEX(PRODUCTORES!$B:$B, MATCH(C280, PRODUCTORES!$F:$F, 0)) & " " & INDEX(PRODUCTORES!$C:$C, MATCH(C280, PRODUCTORES!$F:$F, 0)), IFERROR(INDEX(PRODUCTORES!$B:$B, MATCH(C280, PRODUCTORES!$A:$A, 0)) & " " & INDEX(PRODUCTORES!$C:$C, MATCH(C280, PRODUCTORES!$A:$A, 0)), IFERROR(TRIM(MID(C280, SEARCH(" - ", C280) + 3, 100)), "NO ENCONTRADO"))))} -> GARAY JOSE | E280: {=IF(C280="","",IFERROR(INDEX(PRODUCTORES!$D:$D, MATCH(C280, PRODUCTORES!$F:$F, 0)), IFERROR(INDEX(PRODUCTORES!$D:$D, MATCH(IF(ISNUMBER(SEARCH(" - ", C280)), LEFT(C280, SEARCH(" - ", C280) - 1), C280), PRODUCTORES!$A:$A, 0)), "-")))} -> No | F280: Rúcula | G280: 1
A281: =IF(AND(B281="", C281=""), "", IF(AND(B281=B280, C281=C280, B281<>""), A280, "ENT-" & TEXT(IFERROR(VALUE(RIGHT(A280, 4)), 0) + 1, "0000"))) -> ENT-0077 | B281: 46282 | C281: PROD-145 - GARAY JOSE | D281: {=IF(C281="","",IFERROR(INDEX(PRODUCTORES!$B:$B, MATCH(C281, PRODUCTORES!$F:$F, 0)) & " " & INDEX(PRODUCTORES!$C:$C, MATCH(C281, PRODUCTORES!$F:$F, 0)), IFERROR(INDEX(PRODUCTORES!$B:$B, MATCH(C281, PRODUCTORES!$A:$A, 0)) & " " & INDEX(PRODUCTORES!$C:$C, MATCH(C281, PRODUCTORES!$A:$A, 0)), IFERROR(TRIM(MID(C281, SEARCH(" - ", C281) + 3, 100)), "NO ENCONTRADO"))))} -> GARAY JOSE | E281: {=IF(C281="","",IFERROR(INDEX(PRODUCTORES!$D:$D, MATCH(C281, PRODUCTORES!$F:$F, 0)), IFERROR(INDEX(PRODUCTORES!$D:$D, MATCH(IF(ISNUMBER(SEARCH(" - ", C281)), LEFT(C281, SEARCH(" - ", C281) - 1), C281), PRODUCTORES!$A:$A, 0)), "-")))} -> No | F281: Lechuga (Verde / Mantecosa / Criolla) | G281: 10
A282: =IF(AND(B282="", C282=""), "", IF(AND(B282=B281, C282=C281, B282<>""), A281, "ENT-" & TEXT(IFERROR(VALUE(RIGHT(A281, 4)), 0) + 1, "0000"))) -> ENT-0077 | B282: 46282 | C282: PROD-145 - GARAY JOSE | D282: {=IF(C282="","",IFERROR(INDEX(PRODUCTORES!$B:$B, MATCH(C282, PRODUCTORES!$F:$F, 0)) & " " & INDEX(PRODUCTORES!$C:$C, MATCH(C282, PRODUCTORES!$F:$F, 0)), IFERROR(INDEX(PRODUCTORES!$B:$B, MATCH(C282, PRODUCTORES!$A:$A, 0)) & " " & INDEX(PRODUCTORES!$C:$C, MATCH(C282, PRODUCTORES!$A:$A, 0)), IFERROR(TRIM(MID(C282, SEARCH(" - ", C282) + 3, 100)), "NO ENCONTRADO"))))} -> GARAY JOSE | E282: {=IF(C282="","",IFERROR(INDEX(PRODUCTORES!$D:$D, MATCH(C282, PRODUCTORES!$F:$F, 0)), IFERROR(INDEX(PRODUCTORES!$D:$D, MATCH(IF(ISNUMBER(SEARCH(" - ", C282)), LEFT(C282, SEARCH(" - ", C282) - 1), C282), PRODUCTORES!$A:$A, 0)), "-")))} -> No | F282: Perejil | G282: 4
D283: {=IF(C283="","",IFERROR(INDEX(PRODUCTORES!$B:$B, MATCH(C283, PRODUCTORES!$F:$F, 0)) & " " & INDEX(PRODUCTORES!$C:$C, MATCH(C283, PRODUCTORES!$F:$F, 0)), IFERROR(INDEX(PRODUCTORES!$B:$B, MATCH(C283, PRODUCTORES!$A:$A, 0)) & " " & INDEX(PRODUCTORES!$C:$C, MATCH(C283, PRODUCTORES!$A:$A, 0)), IFERROR(TRIM(MID(C283, SEARCH(" - ", C283) + 3, 100)), "NO ENCONTRADO"))))} | E283: {=IF(C283="","",IFERROR(INDEX(PRODUCTORES!$D:$D, MATCH(C283, PRODUCTORES!$F:$F, 0)), IFERROR(INDEX(PRODUCTORES!$D:$D, MATCH(IF(ISNUMBER(SEARCH(" - ", C283)), LEFT(C283, SEARCH(" - ", C283) - 1), C283), PRODUCTORES!$A:$A, 0)), "-")))}
D284: {=IF(C284="","",IFERROR(INDEX(PRODUCTORES!$B:$B, MATCH(C284, PRODUCTORES!$F:$F, 0)) & " " & INDEX(PRODUCTORES!$C:$C, MATCH(C284, PRODUCTORES!$F:$F, 0)), IFERROR(INDEX(PRODUCTORES!$B:$B, MATCH(C284, PRODUCTORES!$A:$A, 0)) & " " & INDEX(PRODUCTORES!$C:$C, MATCH(C284, PRODUCTORES!$A:$A, 0)), IFERROR(TRIM(MID(C284, SEARCH(" - ", C284) + 3, 100)), "NO ENCONTRADO"))))} | E284: {=IF(C284="","",IFERROR(INDEX(PRODUCTORES!$D:$D, MATCH(C284, PRODUCTORES!$F:$F, 0)), IFERROR(INDEX(PRODUCTORES!$D:$D, MATCH(IF(ISNUMBER(SEARCH(" - ", C284)), LEFT(C284, SEARCH(" - ", C284) - 1), C284), PRODUCTORES!$A:$A, 0)), "-")))}
D285: {=IF(C285="","",IFERROR(INDEX(PRODUCTORES!$B:$B, MATCH(C285, PRODUCTORES!$F:$F, 0)) & " " & INDEX(PRODUCTORES!$C:$C, MATCH(C285, PRODUCTORES!$F:$F, 0)), IFERROR(INDEX(PRODUCTORES!$B:$B, MATCH(C285, PRODUCTORES!$A:$A, 0)) & " " & INDEX(PRODUCTORES!$C:$C, MATCH(C285, PRODUCTORES!$A:$A, 0)), IFERROR(TRIM(MID(C285, SEARCH(" - ", C285) + 3, 100)), "NO ENCONTRADO"))))} | E285: {=IF(C285="","",IFERROR(INDEX(PRODUCTORES!$D:$D, MATCH(C285, PRODUCTORES!$F:$F, 0)), IFERROR(INDEX(PRODUCTORES!$D:$D, MATCH(IF(ISNUMBER(SEARCH(" - ", C285)), LEFT(C285, SEARCH(" - ", C285) - 1), C285), PRODUCTORES!$A:$A, 0)), "-")))}
D286: {=IF(C286="","",IFERROR(INDEX(PRODUCTORES!$B:$B, MATCH(C286, PRODUCTORES!$F:$F, 0)) & " " & INDEX(PRODUCTORES!$C:$C, MATCH(C286, PRODUCTORES!$F:$F, 0)), IFERROR(INDEX(PRODUCTORES!$B:$B, MATCH(C286, PRODUCTORES!$A:$A, 0)) & " " & INDEX(PRODUCTORES!$C:$C, MATCH(C286, PRODUCTORES!$A:$A, 0)), IFERROR(TRIM(MID(C286, SEARCH(" - ", C286) + 3, 100)), "NO ENCONTRADO"))))} | E286: {=IF(C286="","",IFERROR(INDEX(PRODUCTORES!$D:$D, MATCH(C286, PRODUCTORES!$F:$F, 0)), IFERROR(INDEX(PRODUCTORES!$D:$D, MATCH(IF(ISNUMBER(SEARCH(" - ", C286)), LEFT(C286, SEARCH(" - ", C286) - 1), C286), PRODUCTORES!$A:$A, 0)), "-")))}
D287: {=IF(C287="","",IFERROR(INDEX(PRODUCTORES!$B:$B, MATCH(C287, PRODUCTORES!$F:$F, 0)) & " " & INDEX(PRODUCTORES!$C:$C, MATCH(C287, PRODUCTORES!$F:$F, 0)), IFERROR(INDEX(PRODUCTORES!$B:$B, MATCH(C287, PRODUCTORES!$A:$A, 0)) & " " & INDEX(PRODUCTORES!$C:$C, MATCH(C287, PRODUCTORES!$A:$A, 0)), IFERROR(TRIM(MID(C287, SEARCH(" - ", C287) + 3, 100)), "NO ENCONTRADO"))))} | E287: {=IF(C287="","",IFERROR(INDEX(PRODUCTORES!$D:$D, MATCH(C287, PRODUCTORES!$F:$F, 0)), IFERROR(INDEX(PRODUCTORES!$D:$D, MATCH(IF(ISNUMBER(SEARCH(" - ", C287)), LEFT(C287, SEARCH(" - ", C287) - 1), C287), PRODUCTORES!$A:$A, 0)), "-")))}
D288: {=IF(C288="","",IFERROR(INDEX(PRODUCTORES!$B:$B, MATCH(C288, PRODUCTORES!$F:$F, 0)) & " " & INDEX(PRODUCTORES!$C:$C, MATCH(C288, PRODUCTORES!$F:$F, 0)), IFERROR(INDEX(PRODUCTORES!$B:$B, MATCH(C288, PRODUCTORES!$A:$A, 0)) & " " & INDEX(PRODUCTORES!$C:$C, MATCH(C288, PRODUCTORES!$A:$A, 0)), IFERROR(TRIM(MID(C288, SEARCH(" - ", C288) + 3, 100)), "NO ENCONTRADO"))))} | E288: {=IF(C288="","",IFERROR(INDEX(PRODUCTORES!$D:$D, MATCH(C288, PRODUCTORES!$F:$F, 0)), IFERROR(INDEX(PRODUCTORES!$D:$D, MATCH(IF(ISNUMBER(SEARCH(" - ", C288)), LEFT(C288, SEARCH(" - ", C288) - 1), C288), PRODUCTORES!$A:$A, 0)), "-")))}
...

Sheet PRODUCTORES
A1: ID_Productor | B1: Apellido | C1: Nombre | D1: ¿Está Inscripto? | E1: Dirección (Coor) | F1: ID - Apellido y Nombre
A2: PROD-001 | B2: AGUIER | C2: HUGO | D2: No | F2: {=IF(A2:A1000="", "", A2:A1000 & " - " & TRIM(B2:B1000 & " " & C2:C1000))} -> PROD-001 - AGUIER HUGO
A3: PROD-002 | B3: AGUILANTE | C3: ALEJANDRA | D3: No | F3: PROD-002 - AGUILANTE ALEJANDRA
A4: PROD-003 | B4: AGUILANTE | C4: JUAN | D4: No | F4: PROD-003 - AGUILANTE JUAN
A5: PROD-004 | B5: AGUILAR DELGADO | C5: JOSE DAVID | D5: Sí | F5: PROD-004 - AGUILAR DELGADO JOSE DAVID
A6: PROD-005 | B6: AGUILAR | C6: HUGO | D6: No | F6: PROD-005 - AGUILAR HUGO
A7: PROD-006 | B7: AGUILAR | C7: IRENE | D7: No | F7: PROD-006 - AGUILAR IRENE
A8: PROD-007 | B8: AGUILAR OYARZUN | C8: LUIS FERNANDO | D8: Sí | F8: PROD-007 - AGUILAR OYARZUN LUIS FERNANDO
A9: PROD-008 | B9: AGUIRRE | C9: DAMIAN | D9: No | F9: PROD-008 - AGUIRRE DAMIAN
A10: PROD-009 | B10: AGUIRRES | C10: JORGE ANTONIO | D10: Sí | F10: PROD-009 - AGUIRRES JORGE ANTONIO
A11: PROD-010 | B11: AGURTO | C11: MAGALI | D11: No | F11: PROD-010 - AGURTO MAGALI
A12: PROD-011 | B12: ALA SOTO | C12: MICAELA | D12: No | F12: PROD-011 - ALA SOTO MICAELA
A13: PROD-012 | B13: ALAZARD | C13: MARTIN | D13: Sí | F13: PROD-012 - ALAZARD MARTIN
A14: PROD-013 | B14: ALBA HERNANDEZ | C14: NORMA EDITH | D14: Sí | F14: PROD-013 - ALBA HERNANDEZ NORMA EDITH
... A373: PROD-372 | B373: VIVAR | C373: MARIA HERMINIA | D373: Sí | F373: PROD-372 - VIVAR MARIA HERMINIA
D374: Sí
A375: PROD-374 | B375: diaz | C375: axel | D375: No | F375: PROD-374 - diaz axel
D376: Sí

Sheet PRODUCTOS
A1: ID_Producto | B1: Nombre del Producto | C1: Categoría / Grupo | D1: Unidad de Medida | E1: Observaciones
A2: ART-01 | B2: Acelga | C2: Hortaliza de Hoja | D2: Bandeja
A3: ART-02 | B3: Achicoria | C3: Hortaliza de Hoja | D3: Bandeja
A4: ART-03 | B4: Albahaca | C4: Hierba Aromática / Condimento | D4: Bandeja
A5: ART-04 | B5: Apio | C5: Hortaliza de Tallo / Hoja | D5: Bandeja
A6: ART-05 | B6: Bandejas de Variedades / Mix de Hortalizas (Berenjena, Zapallo, Pimiento, Kale) | C6: Presentación / Combo | D6: Bandeja
A7: ART-06 | B7: Berenjena | C7: Hortaliza de Fruto | D7: Bandeja
A8: ART-07 | B8: Brócoli | C8: Hortaliza de Flor / Inflorescencia | D8: Bandeja
A9: ART-08 | B9: Cebolla | C9: Hortaliza de Bulbo | D9: Bandeja
A10: ART-09 | B10: Cebolla de Verdeo / Verdeo | C10: Hortaliza de Bulbo / Tallo | D10: Bandeja
A11: ART-10 | B11: Cilantro | C11: Hierba Aromática / Condimento | D11: Bandeja
A12: ART-11 | B12: Coliflor | C12: Hortaliza de Flor / Inflorescencia | D12: Bandeja
A13: ART-12 | B13: Espinaca | C13: Hortaliza de Hoja | D13: Bandeja
... A28: ART-27 | B28: Zapallo | C28: Hortaliza de Fruto | D28: Bandeja

Sheet INICIO
B2: DASHBOARD
